<sdf version='1.6'>
  <world name='default'>
    
    <!--
    <physics name="1ms" type="ignored">
      <max_step_size>0.001</max_step_size>
      <real_time_factor>1.0</real_time_factor>
    </physics>
    <plugin
      filename="libignition-gazebo-physics-system.so"
      name="ignition::gazebo::systems::Physics">
    </plugin>
    <plugin
      filename="libignition-gazebo-sensors-system.so"
      name="ignition::gazebo::systems::Sensors">
      <render_engine>ogre2</render_engine>
    </plugin>
    <plugin
      filename="libignition-gazebo-scene-broadcaster-system.so"
      name="ignition::gazebo::systems::SceneBroadcaster">
    </plugin>
    -->
    <gui>
        <plugin name="keyboard" filename="libKeyboardGUIPlugin.so"/>
    </gui>

    <light name='sun' type='directional'>
      <cast_shadows>1</cast_shadows>
      <pose>0 0 10 0 -0 0</pose>
      <diffuse>0.8 0.8 0.8 1</diffuse>
      <specular>0.2 0.2 0.2 1</specular>
      <attenuation>
        <range>1000</range>
        <constant>0.9</constant>
        <linear>0.01</linear>
        <quadratic>0.001</quadratic>
      </attenuation>
      <direction>-0.5 0.1 -0.9</direction>
      <spot>
        <inner_angle>0</inner_angle>
        <outer_angle>0</outer_angle>
        <falloff>0</falloff>
      </spot>
    </light>
    <model name='ground_plane'>
      <static>1</static>
      <link name='link'>
        <collision name='collision'>
          <geometry>
            <plane>
              <normal>0 0 1</normal>
              <size>100 100</size>
            </plane>
          </geometry>
          <surface>
            <contact>
              <collide_bitmask>65535</collide_bitmask>
              <ode/>
            </contact>
            <friction>
              <ode>
                <mu>100</mu>
                <mu2>50</mu2>
              </ode>
              <torsional>
                <ode/>
              </torsional>
            </friction>
            <bounce/>
          </surface>
          <max_contacts>10</max_contacts>
        </collision>
        <visual name='visual'>
          <cast_shadows>0</cast_shadows>
          <geometry>
            <plane>
              <normal>0 0 1</normal>
              <size>100 100</size>
            </plane>
          </geometry>
          <material>
            <script>
              <uri>file://media/materials/scripts/gazebo.material</uri>
              <name>Gazebo/Grey</name>
            </script>
          </material>
        </visual>
        <self_collide>0</self_collide>
        <enable_wind>0</enable_wind>
        <kinematic>0</kinematic>
      </link>
    </model>

    <model name="wheel_tracked">
      <pose frame=''>0 4 0.1 0 0 -1.5708</pose>
      <link name='base_link'>
          <pose frame=''>0 0 0 0 -0 0</pose>
          <inertial>
              <pose frame=''>-0.122 0 0.118 1.5708 -0 0</pose>
              <mass>13.14</mass>
              <inertia>
                  <ixx>0.10019</ixx>
                  <ixy>0</ixy>
                  <ixz>0</ixz>
                  <iyy>0.345043</iyy>
                  <iyz>0</iyz>
                  <izz>0.302044</izz>
              </inertia>
          </inertial>
          <collision name='base_link_collision'>
              <pose frame=''>-0.122 0 0.118 0 -0 0</pose>
              <geometry>
                  <box>
                      <size>0.50017 0.24093 0.139</size>
                  </box>
              </geometry>
          </collision>
          <visual name='base_link_visual'>
              <pose frame=''>-0.122 0 0.118 0 -0 0</pose>
              <geometry>
                  <box>
                      <size>0.50017 0.24093 0.139</size>
                  </box>
              </geometry>
          </visual>
          <self_collide>0</self_collide>
          <gravity>1</gravity>
          <kinematic>0</kinematic>
      </link>

      <link name='left_track'>
          <pose frame=''>0 0.1985 0 0 -0 0</pose>
          <inertial>
              <mass>2.06</mass>
              <inertia>
                  <ixx>0.002731</ixx>
                  <ixy>0</ixy>
                  <ixz>0</ixz>
                  <iyy>0.032554</iyy>
                  <iyz>0</iyz>
                  <izz>0.031391</izz>
              </inertia>
          </inertial>
          <collision name='left_track_collision'>
              <pose frame=''>0 0 0.01855 1.5708 -0 1.5708</pose>
              <geometry>
                  <box>
                      <size>0.009728 0.018094 0.05</size>
                  </box>
              </geometry>
              <surface>
                  <friction>
                      <ode>
                          <mu>0.5</mu>
                          <mu2>3.19858</mu2>
                      </ode>
                  </friction>
                  <contact>
                      <collide_bitmask>0</collide_bitmask>
                  </contact>
              </surface>
          </collision>
      </link>
      <joint name='left_track_j' type='revolute'>
          <child>left_track</child>
          <parent>base_link</parent>
          <axis>
              <xyz>0 1 0</xyz>
              <limit>
                  <lower>0</lower>
                  <upper>0</upper>
                  <effort>0</effort>
                  <velocity>4</velocity>
              </limit>
              <use_parent_model_frame>1</use_parent_model_frame>
          </axis>
      </joint>
      <link name='left_track_wheel1'>
          <pose frame=''>0.25 0.1985 0.01855 0 -0 0</pose>
          <inertial>
              <mass>0.5</mass>
              <inertia>
                  <ixx>0.001</ixx>
                  <ixy>0</ixy>
                  <ixz>0</ixz>
                  <iyy>0.001</iyy>
                  <iyz>0</iyz>
                  <izz>0.001</izz>
              </inertia>
          </inertial>
          <collision name='left_track_wheel1_collision'>
              <pose frame=''>0 0 0 1.5708 -0 0</pose>
              <geometry>
                  <cylinder>
                      <length>0.09728</length>
                      <radius>0.09047</radius>
                  </cylinder>
              </geometry>
              <surface>
                  <friction>
                      <ode>
                          <mu>0.5</mu>
                          <mu2>3.19858</mu2>
                      </ode>
                  </friction>
              </surface>
          </collision>
          <visual name='left_track_wheel1_visual'>
              <pose frame=''>0 0 0 1.5708 -0 0</pose>
              <geometry>
                  <cylinder>
                      <length>0.09728</length>
                      <radius>0.09047</radius>
                  </cylinder>
              </geometry>
          </visual>
      </link>
      <joint name='left_track_wheel1_j' type='revolute'>
          <child>left_track_wheel1</child>
          <parent>left_track</parent>
          <axis>
              <xyz>0 1 0</xyz>
              <limit>
                  <lower>-1e+16</lower>
                  <upper>1e+16</upper>
              </limit>
              <use_parent_model_frame>1</use_parent_model_frame>
          </axis>
      </joint>
      <link name='left_track_wheel2'>
          <pose frame=''>0.1786 0.1985 0.01855 0 -0 0</pose>
          <inertial>
              <mass>0.5</mass>
              <inertia>
                  <ixx>0.001</ixx>
                  <ixy>0</ixy>
                  <ixz>0</ixz>
                  <iyy>0.001</iyy>
                  <iyz>0</iyz>
                  <izz>0.001</izz>
              </inertia>
          </inertial>
          <collision name='left_track_wheel2_collision'>
              <pose frame=''>0 0 0 1.5708 -0 0</pose>
              <geometry>
                  <cylinder>
                      <length>0.09728</length>
                      <radius>0.09047</radius>
                  </cylinder>
              </geometry>
              <surface>
                  <friction>
                      <ode>
                          <mu>0.5</mu>
                          <mu2>3.19858</mu2>
                      </ode>
                  </friction>
              </surface>
          </collision>
          <visual name='left_track_wheel2_visual'>
              <pose frame=''>0 0 0 1.5708 -0 0</pose>
              <geometry>
                  <cylinder>
                      <length>0.09728</length>
                      <radius>0.09047</radius>
                  </cylinder>
              </geometry>
          </visual>
      </link>
      <joint name='left_track_wheel2_j' type='revolute'>
          <child>left_track_wheel2</child>
          <parent>left_track</parent>
          <axis>
              <xyz>0 1 0</xyz>
              <limit>
                  <lower>-1e+16</lower>
                  <upper>1e+16</upper>
              </limit>
              <use_parent_model_frame>1</use_parent_model_frame>
          </axis>
      </joint>
      <link name='left_track_wheel3'>
          <pose frame=''>0.1072 0.1985 0.01855 0 -0 0</pose>
          <inertial>
              <mass>0.5</mass>
              <inertia>
                  <ixx>0.001</ixx>
                  <ixy>0</ixy>
                  <ixz>0</ixz>
                  <iyy>0.001</iyy>
                  <iyz>0</iyz>
                  <izz>0.001</izz>
              </inertia>
          </inertial>
          <collision name='left_track_wheel3_collision'>
              <pose frame=''>0 0 0 1.5708 -0 0</pose>
              <geometry>
                  <cylinder>
                      <length>0.09728</length>
                      <radius>0.09047</radius>
                  </cylinder>
              </geometry>
              <surface>
                  <friction>
                      <ode>
                          <mu>0.5</mu>
                          <mu2>3.19858</mu2>
                      </ode>
                  </friction>
              </surface>
          </collision>
          <visual name='left_track_wheel3_visual'>
              <pose frame=''>0 0 0 1.5708 -0 0</pose>
              <geometry>
                  <cylinder>
                      <length>0.09728</length>
                      <radius>0.09047</radius>
                  </cylinder>
              </geometry>
          </visual>
      </link>
      <joint name='left_track_wheel3_j' type='revolute'>
          <child>left_track_wheel3</child>
          <parent>left_track</parent>
          <axis>
              <xyz>0 1 0</xyz>
              <limit>
                  <lower>-1e+16</lower>
                  <upper>1e+16</upper>
              </limit>
              <use_parent_model_frame>1</use_parent_model_frame>
          </axis>
      </joint>
      <link name='left_track_wheel4'>
          <pose frame=''>-0.25 0.1985 0.01855 0 -0 0</pose>
          <inertial>
              <mass>0.5</mass>
              <inertia>
                  <ixx>0.001</ixx>
                  <ixy>0</ixy>
                  <ixz>0</ixz>
                  <iyy>0.001</iyy>
                  <iyz>0</iyz>
                  <izz>0.001</izz>
              </inertia>
          </inertial>
          <collision name='left_track_wheel4_collision'>
              <pose frame=''>0 0 0 1.5708 -0 0</pose>
              <geometry>
                  <cylinder>
                      <length>0.09728</length>
                      <radius>0.09047</radius>
                  </cylinder>
              </geometry>
              <surface>
                  <friction>
                      <ode>
                          <mu>0.5</mu>
                          <mu2>3.19858</mu2>
                      </ode>
                  </friction>
              </surface>
          </collision>
          <visual name='left_track_wheel4_visual'>
              <pose frame=''>0 0 0 1.5708 -0 0</pose>
              <geometry>
                  <cylinder>
                      <length>0.09728</length>
                      <radius>0.09047</radius>
                  </cylinder>
              </geometry>
          </visual>
      </link>
      <joint name='left_track_wheel4_j' type='revolute'>
          <child>left_track_wheel4</child>
          <parent>left_track</parent>
          <axis>
              <xyz>0 1 0</xyz>
              <limit>
                  <lower>-1e+16</lower>
                  <upper>1e+16</upper>
              </limit>
              <use_parent_model_frame>1</use_parent_model_frame>
          </axis>
      </joint>
      <link name='left_track_wheel5'>
          <pose frame=''>-0.0358 0.1985 0.01855 0 -0 0</pose>
          <inertial>
              <mass>0.5</mass>
              <inertia>
                  <ixx>0.001</ixx>
                  <ixy>0</ixy>
                  <ixz>0</ixz>
                  <iyy>0.001</iyy>
                  <iyz>0</iyz>
                  <izz>0.001</izz>
              </inertia>
          </inertial>
          <collision name='left_track_wheel5_collision'>
              <pose frame=''>0 0 0 1.5708 -0 0</pose>
              <geometry>
                  <cylinder>
                      <length>0.09728</length>
                      <radius>0.09047</radius>
                  </cylinder>
              </geometry>
              <surface>
                  <friction>
                      <ode>
                          <mu>0.5</mu>
                          <mu2>3.19858</mu2>
                      </ode>
                  </friction>
              </surface>
          </collision>
          <visual name='left_track_wheel5_visual'>
              <pose frame=''>0 0 0 1.5708 -0 0</pose>
              <geometry>
                  <cylinder>
                      <length>0.09728</length>
                      <radius>0.09047</radius>
                  </cylinder>
              </geometry>
          </visual>
      </link>
      <joint name='left_track_wheel5_j' type='revolute'>
          <child>left_track_wheel5</child>
          <parent>left_track</parent>
          <axis>
              <xyz>0 1 0</xyz>
              <limit>
                  <lower>-1e+16</lower>
                  <upper>1e+16</upper>
              </limit>
              <use_parent_model_frame>1</use_parent_model_frame>
          </axis>
      </joint>
      <link name='left_track_wheel6'>
          <pose frame=''>-0.1072 0.1985 0.01855 0 -0 0</pose>
          <inertial>
              <mass>0.5</mass>
              <inertia>
                  <ixx>0.001</ixx>
                  <ixy>0</ixy>
                  <ixz>0</ixz>
                  <iyy>0.001</iyy>
                  <iyz>0</iyz>
                  <izz>0.001</izz>
              </inertia>
          </inertial>
          <collision name='left_track_wheel6_collision'>
              <pose frame=''>0 0 0 1.5708 -0 0</pose>
              <geometry>
                  <cylinder>
                      <length>0.09728</length>
                      <radius>0.09047</radius>
                  </cylinder>
              </geometry>
              <surface>
                  <friction>
                      <ode>
                          <mu>0.5</mu>
                          <mu2>3.19858</mu2>
                      </ode>
                  </friction>
              </surface>
          </collision>
          <visual name='left_track_wheel6_visual'>
              <pose frame=''>0 0 0 1.5708 -0 0</pose>
              <geometry>
                  <cylinder>
                      <length>0.09728</length>
                      <radius>0.09047</radius>
                  </cylinder>
              </geometry>
          </visual>
          <gravity>1</gravity>
          <velocity_decay/>
          <kinematic>0</kinematic>
      </link>
      <joint name='left_track_wheel6_j' type='revolute'>
          <child>left_track_wheel6</child>
          <parent>left_track</parent>
          <axis>
              <xyz>0 1 0</xyz>
              <limit>
                  <lower>-1e+16</lower>
                  <upper>1e+16</upper>
              </limit>
              <use_parent_model_frame>1</use_parent_model_frame>
          </axis>
      </joint>
      <link name='left_track_wheel7'>
          <pose frame=''>-0.1786 0.1985 0.01855 0 -0 0</pose>
          <inertial>
              <mass>0.5</mass>
              <inertia>
                  <ixx>0.001</ixx>
                  <ixy>0</ixy>
                  <ixz>0</ixz>
                  <iyy>0.001</iyy>
                  <iyz>0</iyz>
                  <izz>0.001</izz>
              </inertia>
          </inertial>
          <collision name='left_track_wheel7_collision'>
              <pose frame=''>0 0 0 1.5708 -0 0</pose>
              <geometry>
                  <cylinder>
                      <length>0.09728</length>
                      <radius>0.09047</radius>
                  </cylinder>
              </geometry>
              <surface>
                  <friction>
                      <ode>
                          <mu>0.5</mu>
                          <mu2>3.19858</mu2>
                      </ode>
                  </friction>
              </surface>
          </collision>
          <visual name='left_track_wheel7_visual'>
              <pose frame=''>0 0 0 1.5708 -0 0</pose>
              <geometry>
                  <cylinder>
                      <length>0.09728</length>
                      <radius>0.09047</radius>
                  </cylinder>
              </geometry>
          </visual>
      </link>
      <joint name='left_track_wheel7_j' type='revolute'>
          <child>left_track_wheel7</child>
          <parent>left_track</parent>
          <axis>
              <xyz>0 1 0</xyz>
              <limit>
                  <lower>-1e+16</lower>
                  <upper>1e+16</upper>
              </limit>
              <use_parent_model_frame>1</use_parent_model_frame>
          </axis>
      </joint>
      <link name='left_track_wheel8'>
          <pose frame=''>0.0358 0.1985 0.01855 0 -0 0</pose>
          <inertial>
              <mass>0.5</mass>
              <inertia>
                  <ixx>0.001</ixx>
                  <ixy>0</ixy>
                  <ixz>0</ixz>
                  <iyy>0.001</iyy>
                  <iyz>0</iyz>
                  <izz>0.001</izz>
              </inertia>
          </inertial>
          <collision name='left_track_wheel8_collision'>
              <pose frame=''>0 0 0 1.5708 -0 0</pose>
              <geometry>
                  <cylinder>
                      <length>0.09728</length>
                      <radius>0.09047</radius>
                  </cylinder>
              </geometry>
              <surface>
                  <friction>
                      <ode>
                          <mu>0.5</mu>
                          <mu2>3.19858</mu2>
                      </ode>
                  </friction>
              </surface>
          </collision>
          <visual name='left_track_wheel8_visual'>
              <pose frame=''>0 0 0 1.5708 -0 0</pose>
              <geometry>
                  <cylinder>
                      <length>0.09728</length>
                      <radius>0.09047</radius>
                  </cylinder>
              </geometry>
          </visual>
      </link>
      <joint name='left_track_wheel8_j' type='revolute'>
          <child>left_track_wheel8</child>
          <parent>left_track</parent>
          <axis>
              <xyz>0 1 0</xyz>
              <limit>
                  <lower>-1e+16</lower>
                  <upper>1e+16</upper>
              </limit>
              <use_parent_model_frame>1</use_parent_model_frame>
          </axis>
      </joint>

      <link name='right_track'>
          <pose frame=''>0 -0.1985 0 0 -0 0</pose>
          <inertial>
              <mass>2.06</mass>
              <inertia>
                  <ixx>0.002731</ixx>
                  <ixy>0</ixy>
                  <ixz>0</ixz>
                  <iyy>0.032554</iyy>
                  <iyz>0</iyz>
                  <izz>0.031391</izz>
              </inertia>
          </inertial>
          <collision name='right_track_collision'>
              <pose frame=''>0 0 0.01855 1.5708 -0 1.5708</pose>
              <geometry>
                  <box>
                      <size>0.009728 0.018094 0.05</size>
                  </box>
              </geometry>
              <surface>
                  <friction>
                      <ode>
                          <mu>0.5</mu>
                          <mu2>3.19858</mu2>
                      </ode>
                  </friction>
                  <contact>
                      <collide_bitmask>0</collide_bitmask>
                  </contact>
              </surface>
          </collision>
      </link>
      <joint name='right_track_j' type='revolute'>
          <child>right_track</child>
          <parent>base_link</parent>
          <axis>
              <xyz>0 1 0</xyz>
              <limit>
                  <lower>0</lower>
                  <upper>0</upper>
                  <effort>0</effort>
                  <velocity>4</velocity>
              </limit>
              <use_parent_model_frame>1</use_parent_model_frame>
          </axis>
      </joint>

      <link name='right_track_wheel1'>
          <pose frame=''>0.25 -0.1985 0.01855 0 -0 0</pose>
          <inertial>
              <mass>0.5</mass>
              <inertia>
                  <ixx>0.001</ixx>
                  <ixy>0</ixy>
                  <ixz>0</ixz>
                  <iyy>0.001</iyy>
                  <iyz>0</iyz>
                  <izz>0.001</izz>
              </inertia>
          </inertial>
          <collision name='right_track_wheel1_collision'>
              <pose frame=''>0 0 0 1.5708 -0 0</pose>
              <geometry>
                  <cylinder>
                      <length>0.09728</length>
                      <radius>0.09047</radius>
                  </cylinder>
              </geometry>
              <surface>
                  <friction>
                      <ode>
                          <mu>0.5</mu>
                          <mu2>3.19858</mu2>
                      </ode>
                  </friction>
              </surface>
          </collision>
          <visual name='right_track_wheel1_visual'>
              <pose frame=''>0 0 0 1.5708 -0 0</pose>
              <geometry>
                  <cylinder>
                      <length>0.09728</length>
                      <radius>0.09047</radius>
                  </cylinder>
              </geometry>
          </visual>
      </link>
      <joint name='right_track_wheel1_j' type='revolute'>
          <child>right_track_wheel1</child>
          <parent>right_track</parent>
          <axis>
              <xyz>0 1 0</xyz>
              <limit>
                  <lower>-1e+16</lower>
                  <upper>1e+16</upper>
              </limit>
              <use_parent_model_frame>1</use_parent_model_frame>
          </axis>
      </joint>
      <link name='right_track_wheel2'>
          <pose frame=''>0.1786 -0.1985 0.01855 0 -0 0</pose>
          <inertial>
              <mass>0.5</mass>
              <inertia>
                  <ixx>0.001</ixx>
                  <ixy>0</ixy>
                  <ixz>0</ixz>
                  <iyy>0.001</iyy>
                  <iyz>0</iyz>
                  <izz>0.001</izz>
              </inertia>
          </inertial>
          <collision name='right_track_wheel2_collision'>
              <pose frame=''>0 0 0 1.5708 -0 0</pose>
              <geometry>
                  <cylinder>
                      <length>0.09728</length>
                      <radius>0.09047</radius>
                  </cylinder>
              </geometry>
              <surface>
                  <friction>
                      <ode>
                          <mu>0.5</mu>
                          <mu2>3.19858</mu2>
                      </ode>
                  </friction>
              </surface>
          </collision>
          <visual name='right_track_wheel2_visual'>
              <pose frame=''>0 0 0 1.5708 -0 0</pose>
              <geometry>
                  <cylinder>
                      <length>0.09728</length>
                      <radius>0.09047</radius>
                  </cylinder>
              </geometry>
          </visual>
      </link>
      <joint name='right_track_wheel2_j' type='revolute'>
          <child>right_track_wheel2</child>
          <parent>right_track</parent>
          <axis>
              <xyz>0 1 0</xyz>
              <limit>
                  <lower>-1e+16</lower>
                  <upper>1e+16</upper>
              </limit>
              <use_parent_model_frame>1</use_parent_model_frame>
          </axis>
      </joint>
      <link name='right_track_wheel3'>
          <pose frame=''>0.1072 -0.1985 0.01855 0 -0 0</pose>
          <inertial>
              <mass>0.5</mass>
              <inertia>
                  <ixx>0.001</ixx>
                  <ixy>0</ixy>
                  <ixz>0</ixz>
                  <iyy>0.001</iyy>
                  <iyz>0</iyz>
                  <izz>0.001</izz>
              </inertia>
          </inertial>
          <collision name='right_track_wheel3_collision'>
              <pose frame=''>0 0 0 1.5708 -0 0</pose>
              <geometry>
                  <cylinder>
                      <length>0.09728</length>
                      <radius>0.09047</radius>
                  </cylinder>
              </geometry>
              <surface>
                  <friction>
                      <ode>
                          <mu>0.5</mu>
                          <mu2>3.19858</mu2>
                      </ode>
                  </friction>
              </surface>
          </collision>
          <visual name='right_track_wheel3_visual'>
              <pose frame=''>0 0 0 1.5708 -0 0</pose>
              <geometry>
                  <cylinder>
                      <length>0.09728</length>
                      <radius>0.09047</radius>
                  </cylinder>
              </geometry>
          </visual>
      </link>
      <joint name='right_track_wheel3_j' type='revolute'>
          <child>right_track_wheel3</child>
          <parent>right_track</parent>
          <axis>
              <xyz>0 1 0</xyz>
              <limit>
                  <lower>-1e+16</lower>
                  <upper>1e+16</upper>
              </limit>
              <use_parent_model_frame>1</use_parent_model_frame>
          </axis>
      </joint>
      <link name='right_track_wheel4'>
          <pose frame=''>-0.25 -0.1985 0.01855 0 -0 0</pose>
          <inertial>
              <mass>0.5</mass>
              <inertia>
                  <ixx>0.001</ixx>
                  <ixy>0</ixy>
                  <ixz>0</ixz>
                  <iyy>0.001</iyy>
                  <iyz>0</iyz>
                  <izz>0.001</izz>
              </inertia>
          </inertial>
          <collision name='right_track_wheel4_collision'>
              <pose frame=''>0 0 0 1.5708 -0 0</pose>
              <geometry>
                  <cylinder>
                      <length>0.09728</length>
                      <radius>0.09047</radius>
                  </cylinder>
              </geometry>
              <surface>
                  <friction>
                      <ode>
                          <mu>0.5</mu>
                          <mu2>3.19858</mu2>
                      </ode>
                  </friction>
              </surface>
          </collision>
          <visual name='right_track_wheel4_visual'>
              <pose frame=''>0 0 0 1.5708 -0 0</pose>
              <geometry>
                  <cylinder>
                      <length>0.09728</length>
                      <radius>0.09047</radius>
                  </cylinder>
              </geometry>
          </visual>
      </link>
      <joint name='right_track_wheel4_j' type='revolute'>
          <child>right_track_wheel4</child>
          <parent>right_track</parent>
          <axis>
              <xyz>0 1 0</xyz>
              <limit>
                  <lower>-1e+16</lower>
                  <upper>1e+16</upper>
              </limit>
              <use_parent_model_frame>1</use_parent_model_frame>
          </axis>
      </joint>
      <link name='right_track_wheel5'>
          <pose frame=''>-0.0358 -0.1985 0.01855 0 -0 0</pose>
          <inertial>
              <mass>0.5</mass>
              <inertia>
                  <ixx>0.001</ixx>
                  <ixy>0</ixy>
                  <ixz>0</ixz>
                  <iyy>0.001</iyy>
                  <iyz>0</iyz>
                  <izz>0.001</izz>
              </inertia>
          </inertial>
          <collision name='right_track_wheel5_collision'>
              <pose frame=''>0 0 0 1.5708 -0 0</pose>
              <geometry>
                  <cylinder>
                      <length>0.09728</length>
                      <radius>0.09047</radius>
                  </cylinder>
              </geometry>
              <surface>
                  <friction>
                      <ode>
                          <mu>0.5</mu>
                          <mu2>3.19858</mu2>
                      </ode>
                  </friction>
              </surface>
          </collision>
          <visual name='right_track_wheel5_visual'>
              <pose frame=''>0 0 0 1.5708 -0 0</pose>
              <geometry>
                  <cylinder>
                      <length>0.09728</length>
                      <radius>0.09047</radius>
                  </cylinder>
              </geometry>
          </visual>
      </link>
      <joint name='right_track_wheel5_j' type='revolute'>
          <child>right_track_wheel5</child>
          <parent>right_track</parent>
          <axis>
              <xyz>0 1 0</xyz>
              <limit>
                  <lower>-1e+16</lower>
                  <upper>1e+16</upper>
              </limit>
              <use_parent_model_frame>1</use_parent_model_frame>
          </axis>
      </joint>
      <link name='right_track_wheel6'>
          <pose frame=''>-0.1072 -0.1985 0.01855 0 -0 0</pose>
          <inertial>
              <mass>0.5</mass>
              <inertia>
                  <ixx>0.001</ixx>
                  <ixy>0</ixy>
                  <ixz>0</ixz>
                  <iyy>0.001</iyy>
                  <iyz>0</iyz>
                  <izz>0.001</izz>
              </inertia>
          </inertial>
          <collision name='right_track_wheel6_collision'>
              <pose frame=''>0 0 0 1.5708 -0 0</pose>
              <geometry>
                  <cylinder>
                      <length>0.09728</length>
                      <radius>0.09047</radius>
                  </cylinder>
              </geometry>
              <surface>
                  <friction>
                      <ode>
                          <mu>0.5</mu>
                          <mu2>3.19858</mu2>
                      </ode>
                  </friction>
              </surface>
          </collision>
          <visual name='right_track_wheel6_visual'>
              <pose frame=''>0 0 0 1.5708 -0 0</pose>
              <geometry>
                  <cylinder>
                      <length>0.09728</length>
                      <radius>0.09047</radius>
                  </cylinder>
              </geometry>
          </visual>
      </link>
      <joint name='right_track_wheel6_j' type='revolute'>
          <child>right_track_wheel6</child>
          <parent>right_track</parent>
          <axis>
              <xyz>0 1 0</xyz>
              <limit>
                  <lower>-1e+16</lower>
                  <upper>1e+16</upper>
              </limit>
              <use_parent_model_frame>1</use_parent_model_frame>
          </axis>
      </joint>
      <link name='right_track_wheel7'>
          <pose frame=''>-0.1786 -0.1985 0.01855 0 -0 0</pose>
          <inertial>
              <mass>0.5</mass>
              <inertia>
                  <ixx>0.001</ixx>
                  <ixy>0</ixy>
                  <ixz>0</ixz>
                  <iyy>0.001</iyy>
                  <iyz>0</iyz>
                  <izz>0.001</izz>
              </inertia>
          </inertial>
          <collision name='right_track_wheel7_collision'>
              <pose frame=''>0 0 0 1.5708 -0 0</pose>
              <geometry>
                  <cylinder>
                      <length>0.09728</length>
                      <radius>0.09047</radius>
                  </cylinder>
              </geometry>
              <surface>
                  <friction>
                      <ode>
                          <mu>0.5</mu>
                          <mu2>3.19858</mu2>
                      </ode>
                  </friction>
              </surface>
          </collision>
          <visual name='right_track_wheel7_visual'>
              <pose frame=''>0 0 0 1.5708 -0 0</pose>
              <geometry>
                  <cylinder>
                      <length>0.09728</length>
                      <radius>0.09047</radius>
                  </cylinder>
              </geometry>
          </visual>
      </link>
      <joint name='right_track_wheel7_j' type='revolute'>
          <child>right_track_wheel7</child>
          <parent>right_track</parent>
          <axis>
              <xyz>0 1 0</xyz>
              <limit>
                  <lower>-1e+16</lower>
                  <upper>1e+16</upper>
              </limit>
              <use_parent_model_frame>1</use_parent_model_frame>
          </axis>
      </joint>
      <link name='right_track_wheel8'>
          <pose frame=''>0.0358 -0.1985 0.01855 0 -0 0</pose>
          <inertial>
              <mass>0.5</mass>
              <inertia>
                  <ixx>0.001</ixx>
                  <ixy>0</ixy>
                  <ixz>0</ixz>
                  <iyy>0.001</iyy>
                  <iyz>0</iyz>
                  <izz>0.001</izz>
              </inertia>
          </inertial>
          <collision name='right_track_wheel8_collision'>
              <pose frame=''>0 0 0 1.5708 -0 0</pose>
              <geometry>
                  <cylinder>
                      <length>0.09728</length>
                      <radius>0.09047</radius>
                  </cylinder>
              </geometry>
              <surface>
                  <friction>
                      <ode>
                          <mu>0.5</mu>
                          <mu2>3.19858</mu2>
                      </ode>
                  </friction>
              </surface>
          </collision>
          <visual name='right_track_wheel8_visual'>
              <pose frame=''>0 0 0 1.5708 -0 0</pose>
              <geometry>
                  <cylinder>
                      <length>0.09728</length>
                      <radius>0.09047</radius>
                  </cylinder>
              </geometry>
          </visual>
      </link>
      <joint name='right_track_wheel8_j' type='revolute'>
          <child>right_track_wheel8</child>
          <parent>right_track</parent>
          <axis>
              <xyz>0 1 0</xyz>
              <limit>
                  <lower>-1e+16</lower>
                  <upper>1e+16</upper>
              </limit>
              <use_parent_model_frame>1</use_parent_model_frame>
          </axis>
      </joint>

      <!-- ****************************** LIDAR *****************************    -->
      
      <link name="lidar_link">    
          <inertial>
          <pose frame=''>0.215 0 0.33 0 0 0</pose>
          <inertia>
              <ixx>0.001</ixx>
              <ixy>0.000</ixy>
              <ixz>0.000</ixz>
              <iyy>0.001</iyy>
              <iyz>0.000</iyz>
              <izz>0.001</izz>
          </inertia>
          <mass>0.114</mass>
          </inertial>

          <collision name="lidar_collision">
          <pose frame=''>0.215 0 0.13 0 0 0</pose>
          <geometry>
              <cylinder>
              <radius>0.0508</radius>
              <length>0.18</length>
              </cylinder>
          </geometry>
          </collision>

          <visual name="lidar_visual">
          <pose frame=''>0.215 0 0.13 0 0 0</pose>
          <geometry>
              <cylinder>
              <radius>0.0508</radius>
              <length>0.18</length>
              </cylinder>
          </geometry>
          <material>
              <ambient>0.0 0.0 0.0 1.0</ambient>
              <diffuse>0.0 0.0 0.0 1.0</diffuse>
              <specular>0.0 0.0 0.0 1.0</specular>
              <emissive>0.0 0.0 0.0 1.0</emissive>
          </material>
          </visual>

          <sensor name="lidar" type="ray">
          <pose frame=''>0.215 0 0.215 0 0 0</pose>
          <always_on>true</always_on>
          <visualize>true</visualize>
          <update_rate>5</update_rate>
          <ray>
              <scan>
              <horizontal>
                  <samples>360</samples>
                  <resolution>1.00000</resolution>
                  <min_angle>0.000000</min_angle>
                  <max_angle>6.280000</max_angle>
              </horizontal>
              <vertical>
                  <samples>16</samples>
                  <resolution>1</resolution>
                  <min_angle>-0.361799</min_angle>
                  <max_angle>0.261799</max_angle>
              </vertical>
              </scan>
              <range>
              <min>0.120000</min>
              <max>7</max>
              <resolution>0.015000</resolution>
              </range>
              <noise>
              <type>gaussian</type>
              <mean>0.0</mean>
              <stddev>0.01</stddev>
              </noise>
          </ray>
          <plugin name="scan" filename="libgazebo_ros_ray_sensor.so">
              <ros>
              <remapping>~/out:=scan</remapping>
              </ros>
              <output_type>sensor_msgs/LaserScan</output_type>
              <frame_name>lidar_link</frame_name>
          </plugin>
          </sensor>
      </link>
      <joint name="lidar_joint" type="fixed">
          <parent>base_link</parent>
          <child>lidar_link</child>
      </joint>

      <plugin name='wheel_tracked_vehicle_controller' filename='libWheelTrackedVehiclePlugin.so'>
          <left_joint>left_track_wheel1_j</left_joint>
          <right_joint>right_track_wheel1_j</right_joint>
          <left_joint>left_track_wheel2_j</left_joint>
          <right_joint>right_track_wheel2_j</right_joint>
          <left_joint>left_track_wheel3_j</left_joint>
          <right_joint>right_track_wheel3_j</right_joint>
          <left_joint>left_track_wheel4_j</left_joint>
          <right_joint>right_track_wheel4_j</right_joint>
          <left_joint>left_track_wheel5_j</left_joint>
          <right_joint>right_track_wheel5_j</right_joint>
          <left_joint>left_track_wheel6_j</left_joint>
          <right_joint>right_track_wheel6_j</right_joint>
          <left_joint>left_track_wheel7_j</left_joint>
          <right_joint>right_track_wheel7_j</right_joint>
          <left_joint>left_track_wheel8_j</left_joint>
          <right_joint>right_track_wheel8_j</right_joint>
          <!-- It'd be nicer to have a higher value here, but there's bug
            https://github.com/osrf/gazebo/issues/2068
            TODO The bug was already fixed but it is still broken. -->
          <track_mu>1.0</track_mu>
          <track_mu2>0.5</track_mu2>
      </plugin>

      <plugin filename="libKeysToCmdVelPlugin.so" name="keyboard_control">
          <cmd_vel_topic>~/wheel_tracked/cmd_vel</cmd_vel_topic>
          <key_controls>
              <!-- WSAD controls + space/Enter for stop -->
              <stop>13</stop>
              <stop>32</stop>
              <accelerate>119</accelerate>
              <decelerate>115</decelerate>
              <left>97</left>
              <right>100</right>
          </key_controls>
      </plugin>
  </model>

    <model name='House 1'>
      <static>1</static>
      <link name='link'>
        <collision name='collision'>
          <geometry>
            <mesh>
              <uri>model://house_1/meshes/house_1.dae</uri>
              <scale>1.5 1.5 1.5</scale>
            </mesh>
          </geometry>
          <max_contacts>10</max_contacts>
          <surface>
            <contact>
              <ode/>
            </contact>
            <bounce/>
            <friction>
              <torsional>
                <ode/>
              </torsional>
              <ode/>
            </friction>
          </surface>
        </collision>
        <visual name='visual'>
          <geometry>
            <mesh>
              <uri>model://house_1/meshes/house_1.dae</uri>
              <scale>1.5 1.5 1.5</scale>
            </mesh>
          </geometry>
          <material>
            <script>
              <uri>model://house_1/materials/scripts</uri>
              <uri>model://house_1/materials/textures</uri>
              <name>House_1/Diffuse</name>
            </script>
            <shader type='normal_map_tangent_space'>
              <normal_map>House_1_Normal.png</normal_map>
            </shader>
          </material>
        </visual>
        <self_collide>0</self_collide>
        <enable_wind>0</enable_wind>
        <kinematic>0</kinematic>
      </link>
      <pose>10 0 0 0 -0 0</pose>
    </model>
    <model name='House 2'>
      <static>1</static>
      <link name='link'>
        <collision name='collision'>
          <geometry>
            <mesh>
              <uri>model://house_2/meshes/house_2.dae</uri>
              <scale>1.5 1.5 1.5</scale>
            </mesh>
          </geometry>
          <max_contacts>10</max_contacts>
          <surface>
            <contact>
              <ode/>
            </contact>
            <bounce/>
            <friction>
              <torsional>
                <ode/>
              </torsional>
              <ode/>
            </friction>
          </surface>
        </collision>
        <visual name='visual'>
          <geometry>
            <mesh>
              <uri>model://house_2/meshes/house_2.dae</uri>
              <scale>1.5 1.5 1.5</scale>
            </mesh>
          </geometry>
          <material>
            <script>
              <uri>model://house_2/materials/scripts</uri>
              <uri>model://house_2/materials/textures</uri>
              <uri>model://house_1/materials/textures</uri>
              <name>House_2/Diffuse</name>
            </script>
            <shader type='normal_map_tangent_space'>
              <normal_map>model://house_1/materials/textures/House_1_Normal.png</normal_map>
            </shader>
          </material>
        </visual>
        <self_collide>0</self_collide>
        <enable_wind>0</enable_wind>
        <kinematic>0</kinematic>
      </link>
      <pose>20 0 0 0 -0 0</pose>
    </model>
    <model name='jersey_barrier'>
      <static>1</static>
      <link name='link'>
        <visual name='visual'>
          <geometry>
            <mesh>
              <uri>model://jersey_barrier/meshes/jersey_barrier.dae</uri>
            </mesh>
          </geometry>
        </visual>
        <collision name='upright'>
          <pose>0 0 0.5715 0 -0 0</pose>
          <geometry>
            <box>
              <size>4.06542 0.3063 1.143</size>
            </box>
          </geometry>
          <max_contacts>10</max_contacts>
          <surface>
            <contact>
              <ode/>
            </contact>
            <bounce/>
            <friction>
              <torsional>
                <ode/>
              </torsional>
              <ode/>
            </friction>
          </surface>
        </collision>
        <collision name='base'>
          <pose>0 0 0.032258 0 -0 0</pose>
          <geometry>
            <box>
              <size>4.06542 0.8107 0.064516</size>
            </box>
          </geometry>
          <max_contacts>10</max_contacts>
          <surface>
            <contact>
              <ode/>
            </contact>
            <bounce/>
            <friction>
              <torsional>
                <ode/>
              </torsional>
              <ode/>
            </friction>
          </surface>
        </collision>
        <collision name='base2'>
          <pose>0 0 0.1 0 -0 0</pose>
          <geometry>
            <box>
              <size>4.06542 0.65 0.1</size>
            </box>
          </geometry>
          <max_contacts>10</max_contacts>
          <surface>
            <contact>
              <ode/>
            </contact>
            <bounce/>
            <friction>
              <torsional>
                <ode/>
              </torsional>
              <ode/>
            </friction>
          </surface>
        </collision>
        <collision name='base3'>
          <pose>0 0 0.2 0 -0 0</pose>
          <geometry>
            <box>
              <size>4.06542 0.5 0.1</size>
            </box>
          </geometry>
          <max_contacts>10</max_contacts>
          <surface>
            <contact>
              <ode/>
            </contact>
            <bounce/>
            <friction>
              <torsional>
                <ode/>
              </torsional>
              <ode/>
            </friction>
          </surface>
        </collision>
        <collision name='left-angle'>
          <pose>0 -0.224 0.2401 0.9 -0 0</pose>
          <geometry>
            <box>
              <size>4.06542 0.5 0.064516</size>
            </box>
          </geometry>
          <max_contacts>10</max_contacts>
          <surface>
            <contact>
              <ode/>
            </contact>
            <bounce/>
            <friction>
              <torsional>
                <ode/>
              </torsional>
              <ode/>
            </friction>
          </surface>
        </collision>
        <collision name='right-angle'>
          <pose>0 0.224 0.2401 -0.9 0 0</pose>
          <geometry>
            <box>
              <size>4.06542 0.5 0.064516</size>
            </box>
          </geometry>
          <max_contacts>10</max_contacts>
          <surface>
            <contact>
              <ode/>
            </contact>
            <bounce/>
            <friction>
              <torsional>
                <ode/>
              </torsional>
              <ode/>
            </friction>
          </surface>
        </collision>
        <self_collide>0</self_collide>
        <enable_wind>0</enable_wind>
        <kinematic>0</kinematic>
      </link>
      <pose>40 0 0 0 -0 0</pose>
    </model>
    <model name='Stop Sign'>
      <static>1</static>
      <link name='link'>
        <collision name='collision'>
          <geometry>
            <mesh>
              <uri>model://stop_sign/meshes/stop_sign.dae</uri>
            </mesh>
          </geometry>
          <max_contacts>10</max_contacts>
          <surface>
            <contact>
              <ode/>
            </contact>
            <bounce/>
            <friction>
              <torsional>
                <ode/>
              </torsional>
              <ode/>
            </friction>
          </surface>
        </collision>
        <visual name='visual'>
          <geometry>
            <mesh>
              <uri>model://stop_sign/meshes/stop_sign.dae</uri>
            </mesh>
          </geometry>
          <material>
            <script>
              <uri>model://stop_sign/materials/scripts</uri>
              <uri>model://stop_sign/materials/textures</uri>
              <name>StopSign/Diffuse</name>
            </script>
          </material>
        </visual>
        <self_collide>0</self_collide>
        <enable_wind>0</enable_wind>
        <kinematic>0</kinematic>
      </link>
      <pose>-30 0 0 0 -0 0</pose>
    </model>
    <model name='Mailbox'>
      <link name='link'>
        <collision name='collision'>
          <geometry>
            <mesh>
              <uri>model://mailbox/meshes/mailbox.dae</uri>
            </mesh>
          </geometry>
          <max_contacts>10</max_contacts>
          <surface>
            <contact>
              <ode/>
            </contact>
            <bounce/>
            <friction>
              <torsional>
                <ode/>
              </torsional>
              <ode/>
            </friction>
          </surface>
        </collision>
        <visual name='visual'>
          <geometry>
            <mesh>
              <uri>model://mailbox/meshes/mailbox.dae</uri>
            </mesh>
          </geometry>
          <material>
            <script>
              <uri>model://mailbox/materials/scripts</uri>
              <uri>model://mailbox/materials/textures</uri>
              <name>Mailbox/Diffuse</name>
            </script>
          </material>
        </visual>
        <self_collide>0</self_collide>
        <inertial>
          <pose>0 0 0 0 -0 0</pose>
          <inertia>
            <ixx>1</ixx>
            <ixy>0</ixy>
            <ixz>0</ixz>
            <iyy>1</iyy>
            <iyz>0</iyz>
            <izz>1</izz>
          </inertia>
          <mass>1</mass>
        </inertial>
        <enable_wind>0</enable_wind>
        <kinematic>0</kinematic>
      </link>
      <pose>0 40 0 0 -0 0</pose>
    </model>
    <model name='Lamp Post'>
      <static>1</static>
      <link name='link'>
        <collision name='collision'>
          <geometry>
            <mesh>
              <uri>model://lamp_post/meshes/lamp_post.dae</uri>
              <scale>3 3 3</scale>
            </mesh>
          </geometry>
          <max_contacts>10</max_contacts>
          <surface>
            <contact>
              <ode/>
            </contact>
            <bounce/>
            <friction>
              <torsional>
                <ode/>
              </torsional>
              <ode/>
            </friction>
          </surface>
        </collision>
        <visual name='visual'>
          <geometry>
            <mesh>
              <uri>model://lamp_post/meshes/lamp_post.dae</uri>
              <scale>3 3 3</scale>
            </mesh>
          </geometry>
        </visual>
        <self_collide>0</self_collide>
        <enable_wind>0</enable_wind>
        <kinematic>0</kinematic>
      </link>
      <pose>0 50 0 0 -0 0</pose>
    </model>
    <model name='Gas Station'>
      <static>1</static>
      <link name='link'>
        <pose>0 0 0 0 -0 0</pose>
        <collision name='collision'>
          <geometry>
            <mesh>
              <uri>model://gas_station/meshes/gas_station.dae</uri>
            </mesh>
          </geometry>
          <max_contacts>10</max_contacts>
          <surface>
            <contact>
              <ode/>
            </contact>
            <bounce/>
            <friction>
              <torsional>
                <ode/>
              </torsional>
              <ode/>
            </friction>
          </surface>
        </collision>
        <visual name='visual'>
          <geometry>
            <mesh>
              <uri>model://gas_station/meshes/gas_station.dae</uri>
            </mesh>
          </geometry>
          <material>
            <script>
              <uri>model://gas_station/materials/scripts</uri>
              <uri>model://gas_station/materials/textures</uri>
              <name>GasStation/Diffuse</name>
            </script>
            <shader type='normal_map_tangent_space'>
              <normal_map>GasStation_Normal.png</normal_map>
            </shader>
          </material>
        </visual>
        <self_collide>0</self_collide>
        <enable_wind>0</enable_wind>
        <kinematic>0</kinematic>
      </link>
      <pose>0 80 0 0 -0 0</pose>
    </model>
    <model name='Fast Food'>
      <static>1</static>
      <link name='link'>
        <pose>0 0 3.15931 0 -0 0</pose>
        <collision name='collision'>
          <geometry>
            <mesh>
              <scale>3 3 2</scale>
              <uri>model://fast_food/meshes/fast_food.dae</uri>
            </mesh>
          </geometry>
          <max_contacts>10</max_contacts>
          <surface>
            <contact>
              <ode/>
            </contact>
            <bounce/>
            <friction>
              <torsional>
                <ode/>
              </torsional>
              <ode/>
            </friction>
          </surface>
        </collision>
        <visual name='visual'>
          <geometry>
            <mesh>
              <scale>3 3 2</scale>
              <uri>model://fast_food/meshes/fast_food.dae</uri>
            </mesh>
          </geometry>
          <material>
            <script>
              <uri>model://fast_food/materials/scripts</uri>
              <uri>model://fast_food/materials/textures</uri>
              <name>FastFood/Diffuse</name>
            </script>
            <shader type='normal_map_tangent_space'>
              <normal_map>FastFood_Normal.png</normal_map>
            </shader>
          </material>
        </visual>
        <self_collide>0</self_collide>
        <enable_wind>0</enable_wind>
        <kinematic>0</kinematic>
      </link>
      <pose>0 90 0 0 -0 0</pose>
    </model>
    <gravity>0 0 -9.8</gravity>
    <magnetic_field>6e-06 2.3e-05 -4.2e-05</magnetic_field>
    <atmosphere type='adiabatic'/>
    <physics type='ode'>
      <max_step_size>0.001</max_step_size>
      <real_time_factor>1</real_time_factor>
      <real_time_update_rate>1000</real_time_update_rate>
    </physics>
    <scene>
      <ambient>0.4 0.4 0.4 1</ambient>
      <background>0.7 0.7 0.7 1</background>
      <shadows>1</shadows>
    </scene>
    <audio>
      <device>default</device>
    </audio>
    <wind/>
    <spherical_coordinates>
      <surface_model>EARTH_WGS84</surface_model>
      <latitude_deg>0</latitude_deg>
      <longitude_deg>0</longitude_deg>
      <elevation>0</elevation>
      <heading_deg>0</heading_deg>
    </spherical_coordinates>
    <model name='school'>
      <static>1</static>
      <link name='link'>
        <collision name='collision'>
          <geometry>
            <mesh>
              <uri>model://school/meshes/school.dae</uri>
            </mesh>
          </geometry>
          <max_contacts>10</max_contacts>
          <surface>
            <contact>
              <ode/>
            </contact>
            <bounce/>
            <friction>
              <torsional>
                <ode/>
              </torsional>
              <ode/>
            </friction>
          </surface>
        </collision>
        <visual name='visual'>
          <geometry>
            <mesh>
              <uri>model://school/meshes/school.dae</uri>
            </mesh>
          </geometry>
        </visual>
        <self_collide>0</self_collide>
        <enable_wind>0</enable_wind>
        <kinematic>0</kinematic>
      </link>
      <pose>20.153 40.3905 0 0 -0 0</pose>
    </model>
    <model name='telephone_pole'>
      <static>1</static>
      <link name='link'>
        <collision name='collision_pole'>
          <pose>0 0 4.572 0 -0 0</pose>
          <geometry>
            <cylinder>
              <radius>0.0779475</radius>
              <length>9.144</length>
            </cylinder>
          </geometry>
          <max_contacts>10</max_contacts>
          <surface>
            <contact>
              <ode/>
            </contact>
            <bounce/>
            <friction>
              <torsional>
                <ode/>
              </torsional>
              <ode/>
            </friction>
          </surface>
        </collision>
        <collision name='collision_cross'>
          <pose>0 -0.098806 8.04836 0 -0 0</pose>
          <geometry>
            <box>
              <size>2.11606 0.041763 0.177806</size>
            </box>
          </geometry>
          <max_contacts>10</max_contacts>
          <surface>
            <contact>
              <ode/>
            </contact>
            <bounce/>
            <friction>
              <torsional>
                <ode/>
              </torsional>
              <ode/>
            </friction>
          </surface>
        </collision>
        <visual name='visual'>
          <geometry>
            <mesh>
              <uri>model://telephone_pole/meshes/telephone_pole.dae</uri>
            </mesh>
          </geometry>
        </visual>
        <self_collide>0</self_collide>
        <enable_wind>0</enable_wind>
        <kinematic>0</kinematic>
      </link>
      <pose>6.41857 26.7291 0 0 -0 0</pose>
    </model>
    <model name='radio_tower'>
      <static>1</static>
      <link name='link'>
        <collision name='collision'>
          <geometry>
            <mesh>
              <uri>model://radio_tower/meshes/radio_tower.dae</uri>
            </mesh>
          </geometry>
          <max_contacts>10</max_contacts>
          <surface>
            <contact>
              <ode/>
            </contact>
            <bounce/>
            <friction>
              <torsional>
                <ode/>
              </torsional>
              <ode/>
            </friction>
          </surface>
        </collision>
        <visual name='visual'>
          <geometry>
            <mesh>
              <uri>model://radio_tower/meshes/radio_tower.dae</uri>
            </mesh>
          </geometry>
        </visual>
        <self_collide>0</self_collide>
        <enable_wind>0</enable_wind>
        <kinematic>0</kinematic>
      </link>
      <pose>38.6701 5.90232 0 0 -0 0</pose>
    </model>
    <model name='Dumpster'>
      <link name='link'>
        <collision name='collision'>
          <geometry>
            <mesh>
              <scale>1.5 1.5 1.5</scale>
              <uri>model://dumpster/meshes/dumpster.dae</uri>
            </mesh>
          </geometry>
          <max_contacts>10</max_contacts>
          <surface>
            <contact>
              <ode/>
            </contact>
            <bounce/>
            <friction>
              <torsional>
                <ode/>
              </torsional>
              <ode/>
            </friction>
          </surface>
        </collision>
        <visual name='visual'>
          <geometry>
            <mesh>
              <scale>1.5 1.5 1.5</scale>
              <uri>model://dumpster/meshes/dumpster.dae</uri>
            </mesh>
          </geometry>
          <material>
            <script>
              <uri>model://dumpster/materials/scripts</uri>
              <uri>model://dumpster/materials/textures</uri>
              <name>Dumpster/Diffuse</name>
            </script>
          </material>
        </visual>
        <self_collide>0</self_collide>
        <inertial>
          <pose>0 0 0 0 -0 0</pose>
          <inertia>
            <ixx>1</ixx>
            <ixy>0</ixy>
            <ixz>0</ixz>
            <iyy>1</iyy>
            <iyz>0</iyz>
            <izz>1</izz>
          </inertia>
          <mass>1</mass>
        </inertial>
        <enable_wind>0</enable_wind>
        <kinematic>0</kinematic>
      </link>
      <pose>16.9696 0.160859 0 0 -0 0</pose>
    </model>
    <state world_name='default'>
      <sim_time>2200 664000000</sim_time>
      <real_time>2359 208550540</real_time>
      <wall_time>1690781860 225436575</wall_time>
      <iterations>2200664</iterations>
      <model name='Big Banana for Scale'>
        <pose>8.13744 31.5438 0 0 -0 0</pose>
        <scale>1 1 1</scale>
        <link name='link'>
          <pose>8.13744 31.5438 0 0 -0 0</pose>
          <velocity>0 0 0 0 -0 0</velocity>
          <acceleration>0 0 0 0 -0 0</acceleration>
          <wrench>0 0 0 0 -0 0</wrench>
        </link>
      </model>
      <model name='Dumpster'>
        <pose>16.3398 0.200736 0.001371 -4e-06 0 0.340443</pose>
        <scale>1 1 1</scale>
        <link name='link'>
          <pose>16.3398 0.200736 0.001371 -4e-06 0 0.340443</pose>
          <velocity>0 0 0 0 -0 0</velocity>
          <acceleration>0 0 -9.8 0 -0 0</acceleration>
          <wrench>0 0 -9.8 0 -0 0</wrench>
        </link>
      </model>
      <model name='Fast Food'>
        <pose>-14.3928 27.2426 0 0 -0 0.569642</pose>
        <scale>1 1 1</scale>
        <link name='link'>
          <pose>-14.3928 27.2426 3.15931 0 -0 0.569642</pose>
          <velocity>0 0 0 0 -0 0</velocity>
          <acceleration>0 0 0 0 -0 0</acceleration>
          <wrench>0 0 0 0 -0 0</wrench>
        </link>
      </model>
      <model name='Gas Station'>
        <pose>-15.8479 10.8664 0 0 0 -0.162919</pose>
        <scale>1 1 1</scale>
        <link name='link'>
          <pose>-15.8479 10.8664 0 0 0 -0.162919</pose>
          <velocity>0 0 0 0 -0 0</velocity>
          <acceleration>0 0 0 0 -0 0</acceleration>
          <wrench>0 0 0 0 -0 0</wrench>
        </link>
      </model>
      <model name='House 1'>
        <pose>9.70844 -14.0659 0 0 0 -1.8786</pose>
        <scale>1 1 1</scale>
        <link name='link'>
          <pose>9.70844 -14.0659 0 0 0 -1.8786</pose>
          <velocity>0 0 0 0 -0 0</velocity>
          <acceleration>0 0 0 0 -0 0</acceleration>
          <wrench>0 0 0 0 -0 0</wrench>
        </link>
      </model>
      <model name='House 2'>
        <pose>22.4925 4.83393 0 0 -0 0.380911</pose>
        <scale>1 1 1</scale>
        <link name='link'>
          <pose>22.4925 4.83393 0 0 -0 0.380911</pose>
          <velocity>0 0 0 0 -0 0</velocity>
          <acceleration>0 0 0 0 -0 0</acceleration>
          <wrench>0 0 0 0 -0 0</wrench>
        </link>
      </model>
      <model name='Lamp Post'>
        <pose>11.8722 31.358 0 0 -0 0</pose>
        <scale>1 1 1</scale>
        <link name='link'>
          <pose>11.8722 31.358 0 0 -0 0</pose>
          <velocity>0 0 0 0 -0 0</velocity>
          <acceleration>0 0 0 0 -0 0</acceleration>
          <wrench>0 0 0 0 -0 0</wrench>
        </link>
      </model>
      <model name='Mailbox'>
        <pose>6.96462 30.24 -9e-06 4e-06 -7e-06 -2.08263</pose>
        <scale>1 1 1</scale>
        <link name='link'>
          <pose>6.96462 30.24 -9e-06 4e-06 -7e-06 -2.08263</pose>
          <velocity>0 0 0 0 -0 0</velocity>
          <acceleration>0 0 -9.8 0 -0 0</acceleration>
          <wrench>0 0 -9.8 0 -0 0</wrench>
        </link>
      </model>
      <model name='Stop Sign'>
        <pose>1262.08 -958.397 -7.40689 0 -0 0</pose>
        <scale>1 1 1</scale>
        <link name='link'>
          <pose>1262.08 -958.397 -7.40689 0 -0 0</pose>
          <velocity>0 0 0 0 -0 0</velocity>
          <acceleration>0 0 0 0 -0 0</acceleration>
          <wrench>0 0 0 0 -0 0</wrench>
        </link>
      </model>
      <model name='electrical_box'>
        <pose>4.3436 29.144 0 0 -0 0</pose>
        <scale>1 1 1</scale>
        <link name='link'>
          <pose>4.3436 29.144 0 -1.57159 3e-06 3.14159</pose>
          <velocity>0 0 0 0 -0 0</velocity>
          <acceleration>0 0 0 0 -0 0</acceleration>
          <wrench>0 0 0 0 -0 0</wrench>
        </link>
      </model>
      <model name='gazebo'>
        <pose>50.8045 11.6873 0 0 -0 0</pose>
        <scale>1 1 1</scale>
        <link name='link'>
          <pose>50.8045 11.6873 0 0 -0 0</pose>
          <velocity>0 0 0 0 -0 0</velocity>
          <acceleration>0 0 0 0 -0 0</acceleration>
          <wrench>0 0 0 0 -0 0</wrench>
        </link>
      </model>
      <model name='ground_plane'>
        <pose>0 0 0 0 -0 0</pose>
        <scale>1 1 1</scale>
        <link name='link'>
          <pose>0 0 0 0 -0 0</pose>
          <velocity>0 0 0 0 -0 0</velocity>
          <acceleration>0 0 0 0 -0 0</acceleration>
          <wrench>0 0 0 0 -0 0</wrench>
        </link>
      </model>
      <model name='ground_plane_0'>
        <pose>-0.019574 99.5796 0 0 -0 0</pose>
        <scale>1 1 1</scale>
        <link name='link'>
          <pose>-0.019574 99.5796 0 0 -0 0</pose>
          <velocity>0 0 0 0 -0 0</velocity>
          <acceleration>0 0 0 0 -0 0</acceleration>
          <wrench>0 0 0 0 -0 0</wrench>
        </link>
      </model>
      <model name='ground_plane_1'>
        <pose>99.941 0.034553 0 0 -0 0</pose>
        <scale>1 1 1</scale>
        <link name='link'>
          <pose>99.941 0.034553 0 0 -0 0</pose>
          <velocity>0 0 0 0 -0 0</velocity>
          <acceleration>0 0 0 0 -0 0</acceleration>
          <wrench>0 0 0 0 -0 0</wrench>
        </link>
      </model>
      <model name='ground_plane_2'>
        <pose>99.1867 98.1749 0 0 -0 0</pose>
        <scale>1 1 1</scale>
        <link name='link'>
          <pose>99.1867 98.1749 0 0 -0 0</pose>
          <velocity>0 0 0 0 -0 0</velocity>
          <acceleration>0 0 0 0 -0 0</acceleration>
          <wrench>0 0 0 0 -0 0</wrench>
        </link>
      </model>
      <model name='jersey_barrier'>
        <pose>13.5621 -1.95096 0 0 -0 1.17116</pose>
        <scale>1 1 1</scale>
        <link name='link'>
          <pose>13.5621 -1.95096 0 0 -0 1.17116</pose>
          <velocity>0 0 0 0 -0 0</velocity>
          <acceleration>0 0 0 0 -0 0</acceleration>
          <wrench>0 0 0 0 -0 0</wrench>
        </link>
      </model>
      <model name='radio_tower'>
        <pose>38.6701 5.90232 0 0 -0 0</pose>
        <scale>1 1 1</scale>
        <link name='link'>
          <pose>38.6701 5.90232 0 0 -0 0</pose>
          <velocity>0 0 0 0 -0 0</velocity>
          <acceleration>0 0 0 0 -0 0</acceleration>
          <wrench>0 0 0 0 -0 0</wrench>
        </link>
      </model>
      <model name='school'>
        <pose>23.5758 47.1153 0 0 -0 0</pose>
        <scale>1 1 1</scale>
        <link name='link'>
          <pose>23.5758 47.1153 0 0 -0 0</pose>
          <velocity>0 0 0 0 -0 0</velocity>
          <acceleration>0 0 0 0 -0 0</acceleration>
          <wrench>0 0 0 0 -0 0</wrench>
        </link>
      </model>
      <model name='telephone_pole'>
        <pose>2.61397 30.0372 0 0 -0 0</pose>
        <scale>1 1 1</scale>
        <link name='link'>
          <pose>2.61397 30.0372 0 0 -0 0</pose>
          <velocity>0 0 0 0 -0 0</velocity>
          <acceleration>0 0 0 0 -0 0</acceleration>
          <wrench>0 0 0 0 -0 0</wrench>
        </link>
      </model>
      <light name='sun'>
        <pose>0 0 10 0 -0 0</pose>
      </light>
    </state>
    <model name='ground_plane_0'>
      <static>1</static>
      <link name='link'>
        <collision name='collision'>
          <geometry>
            <plane>
              <normal>0 0 1</normal>
              <size>100 100</size>
            </plane>
          </geometry>
          <surface>
            <contact>
              <collide_bitmask>65535</collide_bitmask>
              <ode/>
            </contact>
            <friction>
              <ode>
                <mu>100</mu>
                <mu2>50</mu2>
              </ode>
              <torsional>
                <ode/>
              </torsional>
            </friction>
            <bounce/>
          </surface>
          <max_contacts>10</max_contacts>
        </collision>
        <visual name='visual'>
          <cast_shadows>0</cast_shadows>
          <geometry>
            <plane>
              <normal>0 0 1</normal>
              <size>100 100</size>
            </plane>
          </geometry>
          <material>
            <script>
              <uri>file://media/materials/scripts/gazebo.material</uri>
              <name>Gazebo/Grey</name>
            </script>
          </material>
        </visual>
        <self_collide>0</self_collide>
        <enable_wind>0</enable_wind>
        <kinematic>0</kinematic>
      </link>
      <pose>-0.019574 99.5796 0 0 -0 0</pose>
    </model>
    <model name='ground_plane_1'>
      <static>1</static>
      <link name='link'>
        <collision name='collision'>
          <geometry>
            <plane>
              <normal>0 0 1</normal>
              <size>100 100</size>
            </plane>
          </geometry>
          <surface>
            <contact>
              <collide_bitmask>65535</collide_bitmask>
              <ode/>
            </contact>
            <friction>
              <ode>
                <mu>100</mu>
                <mu2>50</mu2>
              </ode>
              <torsional>
                <ode/>
              </torsional>
            </friction>
            <bounce/>
          </surface>
          <max_contacts>10</max_contacts>
        </collision>
        <visual name='visual'>
          <cast_shadows>0</cast_shadows>
          <geometry>
            <plane>
              <normal>0 0 1</normal>
              <size>100 100</size>
            </plane>
          </geometry>
          <material>
            <script>
              <uri>file://media/materials/scripts/gazebo.material</uri>
              <name>Gazebo/Grey</name>
            </script>
          </material>
        </visual>
        <self_collide>0</self_collide>
        <enable_wind>0</enable_wind>
        <kinematic>0</kinematic>
      </link>
      <pose>99.941 0.034553 0 0 -0 0</pose>
    </model>
    <model name='ground_plane_2'>
      <static>1</static>
      <link name='link'>
        <collision name='collision'>
          <geometry>
            <plane>
              <normal>0 0 1</normal>
              <size>100 100</size>
            </plane>
          </geometry>
          <surface>
            <contact>
              <collide_bitmask>65535</collide_bitmask>
              <ode/>
            </contact>
            <friction>
              <ode>
                <mu>100</mu>
                <mu2>50</mu2>
              </ode>
              <torsional>
                <ode/>
              </torsional>
            </friction>
            <bounce/>
          </surface>
          <max_contacts>10</max_contacts>
        </collision>
        <visual name='visual'>
          <cast_shadows>0</cast_shadows>
          <geometry>
            <plane>
              <normal>0 0 1</normal>
              <size>100 100</size>
            </plane>
          </geometry>
          <material>
            <script>
              <uri>file://media/materials/scripts/gazebo.material</uri>
              <name>Gazebo/Grey</name>
            </script>
          </material>
        </visual>
        <self_collide>0</self_collide>
        <enable_wind>0</enable_wind>
        <kinematic>0</kinematic>
      </link>
      <pose>99.1867 98.1749 0 0 -0 0</pose>
    </model>
    <model name='gazebo'>
      <static>1</static>
      <link name='link'>
        <collision name='collision'>
          <geometry>
            <mesh>
              <scale>3 3 2.5</scale>
              <uri>model://gazebo/meshes/gazebo.dae</uri>
            </mesh>
          </geometry>
          <max_contacts>10</max_contacts>
          <surface>
            <contact>
              <ode/>
            </contact>
            <bounce/>
            <friction>
              <torsional>
                <ode/>
              </torsional>
              <ode/>
            </friction>
          </surface>
        </collision>
        <visual name='visual'>
          <geometry>
            <mesh>
              <scale>3 3 2.5</scale>
              <uri>model://gazebo/meshes/gazebo.dae</uri>
            </mesh>
          </geometry>
        </visual>
        <self_collide>0</self_collide>
        <enable_wind>0</enable_wind>
        <kinematic>0</kinematic>
      </link>
      <pose>50.8045 11.6873 0 0 -0 0</pose>
    </model>

    <model name='simulated_vehicle'> <!-- The main car -->
      <pose>-15 3 0.325 0 0 0.0</pose>
      <link name='chassis'>
        <pose>-0.151427 -0 0.175 0 -0 0</pose>
        <inertial>
          <mass>1.14395</mass>
          <inertia>
            <ixx>0.126164</ixx>
            <ixy>0</ixy>
            <ixz>0</ixz>
            <iyy>0.416519</iyy>
            <iyz>0</iyz>
            <izz>0.481014</izz>
          </inertia>
        </inertial>
        <visual name='visual'>
          <geometry>
            <box>
              <size>2.01142 1 0.568726</size>
            </box>
          </geometry>
          <material>
            <ambient>0.5 0.5 1.0 1</ambient>
            <diffuse>0.5 0.5 1.0 1</diffuse>
            <specular>0.0 0.0 1.0 1</specular>
          </material>
        </visual>
        <collision name='collision'>
          <geometry>
            <box>
              <size>2.01142 1 0.568726</size>
            </box>
          </geometry>
        </collision>
      </link>
    </model>
    <gui fullscreen='0'>
      <camera name='user_camera'>
        <pose>-50.3165 -89.3046 59.2438 0 0.48197 0.814362</pose>
        <view_controller>orbit</view_controller>
        <projection_type>perspective</projection_type>
      </camera>
    </gui>
  </world>
</sdf>
